<?xml version="1.0"?>
<robot name="example">

    <link name="link1">
        <visual>
            <geometry>
                <box size="0.1 0.1 0.5" />
            </geometry>
            <material name="green">
                <color rgba="0 1 0 1" />
            </material>
        </visual>
    </link>

    <link name="link2">
        <visual>
            <origin xyz="0 0 0" rpy="0 0 0" />
            <geometry>
                <mesh filename="package://urdf_example/urdf/mantis_frame.stl" scale="1 1 1" />
            </geometry>
            <material name="blue">
                <color rgba="0 0 1 1" />
            </material>
        </visual>
    </link>

    <joint name="joint1" type="revolute">
        <parent link="link1" />
        <child link="link2" />
        <origin xyz="1 0 0" rpy="0 0 0" />
        <axis xyz="0 0 1" />
        <limit effort="1000.0" velocity="3.0" />
    </joint>

</robot>