<?xml version="1.0"?>
<robot name="mantis" xmlns:xacro="http://www.ros.org/wiki/xacro">

  <xacro:property name="front_caster_x" value="0.36" />
  <xacro:property name="front_caster_y" value="0.275" />
  <xacro:property name="rear_caster_x" value="-0.435" />
  <xacro:property name="rear_caster_y" value="0.105" />
  <xacro:property name="frame_height" value="0.18" />
  <xacro:property name="wheel_radius" value="0.165" />
  <xacro:property name="wheel_thickness" value="0.05" />
  <xacro:property name="wheel_mass" value="5.0" />
  <xacro:property name="caster_radius" value="0.08" />
  <xacro:property name="drive_wheel_offset" value="0.29" />

  <!-- Include separate URDF file with just the Gazebo elements -->
  <xacro:include filename="$(find mantis_model)/urdf/mantis_gazebo.urdf" />
  
  <!-- Include a LIDAR and camera sensor -->
  <xacro:include filename="$(find ugv_lecture_gazebo)/urdf/hokuyo.urdf.xacro" />
  <xacro:include filename="$(find ugv_lecture_gazebo)/urdf/audibot_camera.urdf.xacro" />
  <xacro:hokuyo name="laser" parent_frame="body_link" x="0.17" y="0.0" z="0.22" roll="0" pitch="0" yaw="0" />
  <xacro:audibot_camera name="camera" tf_prefix="" parent_link="body_link" x="-0.15" y="0.0" z="1.5" roll="0" pitch="0.5" yaw="0" />

  <!-- Reusable macro for a drive wheel -->
  <xacro:macro name="drive_wheel" params="name y_offset">
    <link name="${name}_wheel">
      <visual>
        <geometry>
          <cylinder length="${wheel_thickness}" radius="${wheel_radius}" />
        </geometry>
        <material name="dark_gray" />
      </visual>

      <visual>
        <geometry>
          <box size="0.02 0.1 0.07" />
        </geometry>
        <material name="dark_gray" />
      </visual>

      <visual>
        <geometry>
          <box size="0.1 0.02 0.07" />
        </geometry>
        <material name="dark_gray" />
      </visual>

      <collision>
        <geometry>
          <cylinder length="${wheel_thickness}" radius="${wheel_radius}" />
        </geometry>
      </collision>

      <inertial>
        <mass value="${wheel_mass}" />
        <inertia ixx="${wheel_mass/12 * (3 * wheel_radius * wheel_radius + wheel_thickness * wheel_thickness)}" ixy="0" ixz="0"
                 iyy="${wheel_mass/12 * (3 * wheel_radius * wheel_radius + wheel_thickness * wheel_thickness)}" iyz="0"
                 izz="${0.5 * wheel_mass * wheel_radius * wheel_radius}" />
      </inertial>
    </link>

    <joint name="${name}_wheel_joint" type="continuous">
      <parent link="body_link" />
      <child link="${name}_wheel" />
      <origin xyz="0 ${y_offset} 0" rpy="-1.5707 0 0" />
      <axis xyz="0 0 1" />
      <limit effort="1000.0" velocity="50.0" />
    </joint>
  </xacro:macro>

  <!-- Reusable macro for a caster wheel -->
  <xacro:macro name="caster_wheel" params="name x_offset y_offset">
    <link name="${name}_caster">
      <visual>
        <geometry>
          <cylinder length="${wheel_thickness}" radius="${caster_radius}" />
        </geometry>
        <material name="dark_gray" />
      </visual>

      <collision>
        <geometry>
          <cylinder length="${wheel_thickness}" radius="${caster_radius}" />
        </geometry>
      </collision>

      <inertial>
        <mass value="1.0" />
        <inertia ixx="1.0" ixy="0" ixz="0" iyy="1.0" iyz="0" izz="1.0" />
      </inertial>
    </link>

    <joint name="${name}_caster_joint" type="fixed">
      <parent link="body_link" />
      <child link="${name}_caster" />
      <origin xyz="${x_offset} ${y_offset} ${-(wheel_radius - caster_radius)}" rpy="-1.5707 0 0" />
    </joint>

  </xacro:macro>

  <xacro:drive_wheel name="left" y_offset="${drive_wheel_offset}" />
  <xacro:drive_wheel name="right" y_offset="${-drive_wheel_offset}" />

  <xacro:caster_wheel name="fl" x_offset="${front_caster_x}" y_offset="${front_caster_y}" />
  <xacro:caster_wheel name="fr" x_offset="${front_caster_x}" y_offset="${-front_caster_y}" />
  <xacro:caster_wheel name="rl" x_offset="${rear_caster_x}" y_offset="${rear_caster_y}" />
  <xacro:caster_wheel name="rr" x_offset="${rear_caster_x}" y_offset="${-rear_caster_y}" />

  <link name="base_footprint" />

  <link name="body_link">
    <visual>
      <origin xyz="0 0 0" rpy="0 0 0" />
      <geometry>
        <mesh filename="package://mantis_model/meshes/mantis_base.stl" scale="1 1 1" />
      </geometry>
      <material name="gray" />
    </visual>
    <visual>
      <origin xyz="0 0 ${frame_height}" rpy="0 0 0" />
      <geometry>
        <mesh filename="package://mantis_model/meshes/mantis_frame.stl" scale="1 1 1" />
      </geometry>
      <material name="gray" />
    </visual>
    <visual>
      <origin xyz="0 0 ${frame_height}" rpy="0 0 0" />
      <geometry>
        <box size="0.5 0.6 0.0127" />
      </geometry>
      <material name="gray" />
    </visual>

    <collision>
      <geometry>
        <mesh filename="package://mantis_model/meshes/mantis_base.stl" scale="1 1 1" />
      </geometry>
    </collision>

    <collision>
      <origin xyz="0 0 ${frame_height}" rpy="0 0 0" />
      <geometry>
        <mesh filename="package://mantis_model/meshes/mantis_frame.stl" scale="1 1 1" />
      </geometry>
    </collision>

    <inertial>
      <mass value="100.0" />
      <inertia ixx="10.0" ixy="0" ixz="0" iyy="10.0" iyz="0" izz="10.0" />
    </inertial>
  </link>

  <joint name="base_joint" type="fixed">
    <parent link="base_footprint" />
    <child link="body_link" />
    <origin xyz="0 0 ${wheel_radius}" rpy="0 0 0" />
  </joint>

  <material name="gray">
    <color rgba="0.4 0.4 0.4 1.0" />
  </material>

  <material name="dark_gray">
    <color rgba="0.1 0.1 0.1 1.0" />
  </material>

</robot>
